Workbook

Sheet Sheet1
A1: Order ID | B1: Customer Name | C1: Order Date | D1: Ship Date | E1: Project status | F1: Order Year | G1: Order Month | H1: Weekday | J1: TASK 12-Date & Time Functions
A2: IN-2014-CR127307-41929 | B2: Craig Reiter | C2: 41919 | D2: 41930 | E2: =IF(Sheet1!$D2<=TODAY(),"COMPLETED","PENDING") -> COMPLETED | F2: =YEAR(Sheet1!$C2) -> 2014 | G2: =MONTH(Sheet1!$C2) -> 10 | H2: =WEEKDAY(Sheet1!$C2) -> 3
A3: ES-2014-KM1637548-41667 | B3: Katherine Murray | C3: 41667 | D3: 41669 | E3: =IF(Sheet1!$D3<=TODAY(),"COMPLETED","PENDING") -> COMPLETED | F3: 2014 | G3: =WEEKDAY(Sheet1!$C3) -> 3 | J3: 1.Today function using current date | K3: =TODAY() -> 45977
B4: Rick Hansen | C4: 41948 | D4: 41949 | E4: =IF(Sheet1!$D4<=TODAY(),"COMPLETED","PENDING") -> COMPLETED | F4: =YEAR(Sheet1!$C4) -> 2014 | G4: =MONTH(Sheet1!$C4) -> 11 | H4: =WEEKDAY(Sheet1!$C4) -> 4 | J4: 2.Now function using current | K4: =NOW() -> 45977.721
A5: IN-2014-JM156557-41818 | B5: Jim Mitchum | C5: 41818 | D5: 41821 | E5: =IF(Sheet1!$D5<=TODAY(),"COMPLETED","PENDING") -> COMPLETED | F5: =YEAR(Sheet1!$C5) -> 2014 | G5: =MONTH(Sheet1!$C5) -> 6 | H5: =WEEKDAY(Sheet1!$C5) -> 7 | J5: date and time mention
B6: Toby Swindell | C6: 41219 | D6: 41221 | E6: =IF(Sheet1!$D6<=TODAY(),"COMPLETED","PENDING") -> COMPLETED | F6: =YEAR(Sheet1!$C6) -> 2012 | G6: =MONTH(Sheet1!$C6) -> 11 | H6: =WEEKDAY(Sheet1!$C6) -> 3 | J6: 3.Oder date column using YEAR,
A7: IN-2013-MB1808592-41378 | B7: Mick Brown | E7: =IF(Sheet1!$D7<=TODAY(),"COMPLETED","PENDING") -> COMPLETED | F7: =YEAR(Sheet1!$C7) -> 1900 | G7: =MONTH(Sheet1!$C7) -> 1 | H7: =WEEKDAY(Sheet1!$C7) -> 7 | J7: MONTH,WEEKDAY function
A8: CA-2014-AB10015140-41954 | B8: Aaron Bergman | C8: 41954 | D8: 41956 | E8: =IF(Sheet1!$D8<=TODAY(),"COMPLETED","PENDING") -> COMPLETED | F8: =YEAR(Sheet1!$C8) -> 2014 | G8: =MONTH(Sheet1!$C8) -> 11 | H8: =WEEKDAY(Sheet1!$C8) -> 3 | J8: 4.IF statement using the contion
A9: CA-2012-AB10015140-40974 | B9: Aaron Bergman | C9: 40974 | D9: 40975 | E9: =IF(Sheet1!$D9<=TODAY(),"COMPLETED","PENDING") -> COMPLETED | F9: =YEAR(Sheet1!$C9) -> 2012 | G9: =MONTH(Sheet1!$C9) -> 3 | H9: =WEEKDAY(Sheet1!$C9) -> 3 | J9: <=today completed project else pending project
A10: CA-2012-AB10015140-40974 | B10: Aaron Bergman | C10: 40974 | D10: 40975 | E10: =IF(Sheet1!$D10<=TODAY(),"COMPLETED","PENDING") -> COMPLETED | F10: =YEAR(Sheet1!$C10) -> 2012 | G10: =MONTH(Sheet1!$C10) -> 3 | H10: =WEEKDAY(Sheet1!$C10) -> 3
A11: ID-2013-AJ107801-41383 | B11: Anthony Jacobs | C11: 41383 | E11: =IF(Sheet1!$D11<=TODAY(),"COMPLETED","PENDING") -> PENDING | F11: =YEAR(Sheet1!$C11) -> 2013 | G11: =MONTH(Sheet1!$C11) -> 4 | H11: =WEEKDAY(Sheet1!$C11) -> 6
A12: SA-2012-MM7260110-41269 | B12: Magdelene Morse | C12: 41269 | E12: =IF(Sheet1!$D12<=TODAY(),"COMPLETED","PENDING") -> COMPLETED | F12: =YEAR(Sheet1!$C12) -> 2012 | G12: =MONTH(Sheet1!$C12) -> 12 | H12: =WEEKDAY(Sheet1!$C12) -> 4
A13: MX-2013-VF2171518-41591 | B13: Vicky Freymann | C13: 41591 | D13: 41591 | E13: =IF(Sheet1!$D13<=TODAY(),"COMPLETED","PENDING") -> COMPLETED | F13: =YEAR(Sheet1!$C13) -> 2013 | G13: =MONTH(Sheet1!$C13) -> 11 | H13: =WEEKDAY(Sheet1!$C13) -> 4
A14: IN-2014-PF1912027-41796 | B14: Peter Fuller | C14: 41796 | D14: 41798 | E14: =IF(Sheet1!$D14<=TODAY(),"COMPLETED","PENDING") -> COMPLETED | F14: =YEAR(Sheet1!$C14) -> 2014 | G14: =MONTH(Sheet1!$C14) -> 6 | H14: =WEEKDAY(Sheet1!$C14) -> 6
A15: ES-2015-BP1118545-42216 | B15: Ben Peterman | C15: 42216 | D15: 42219 | E15: =IF(Sheet1!$D15<=TODAY(),"COMPLETED","PENDING") -> COMPLETED | F15: =YEAR(Sheet1!$C15) -> 2015 | G15: =MONTH(Sheet1!$C15) -> 7 | H15: =WEEKDAY(Sheet1!$C15) -> 6
A16: CA-2012-AB10015140-40958 | B16: Aaron Bergman | C16: 40958 | D16: 40964 | E16: =IF(Sheet1!$D16<=TODAY(),"COMPLETED","PENDING") -> COMPLETED | F16: =YEAR(Sheet1!$C16) -> 2012 | G16: =MONTH(Sheet1!$C16) -> 2 | H16: =WEEKDAY(Sheet1!$C16) -> 1
A17: ES-2015-PJ1883564-42255 | C17: 42255 | D17: 42261 | E17: =IF(Sheet1!$D17<=TODAY(),"COMPLETED","PENDING") -> COMPLETED | F17: =YEAR(Sheet1!$C17) -> 2015 | G17: =MONTH(Sheet1!$C17) -> 9 | H17: =WEEKDAY(Sheet1!$C17) -> 3
A18: IN-2015-JS156857-42035 | B18: Jim Sink | C18: 42035 | D18: 42036 | E18: =IF(Sheet1!$D18<=TODAY(),"COMPLETED","PENDING") -> COMPLETED | F18: =YEAR(Sheet1!$C18) -> 2015 | G18: =MONTH(Sheet1!$C18) -> 1 | H18: =WEEKDAY(Sheet1!$C18) -> 7
A19: TZ-2015-RH9555129-42343 | B19: Ritsa Hightower | C19: 42343 | D19: 42345 | E19: =IF(Sheet1!$D19<=TODAY(),"COMPLETED","PENDING") -> COMPLETED | F19: =YEAR(Sheet1!$C19) -> 2015 | G19: =MONTH(Sheet1!$C19) -> 12 | H19: =WEEKDAY(Sheet1!$C19) -> 7
A20: PL-2013-AB600103-41494 | B20: Ann Blume | C20: 41494 | D20: 41496 | E20: =IF(Sheet1!$D20<=TODAY(),"COMPLETED","PENDING") -> COMPLETED | F20: =YEAR(Sheet1!$C20) -> 2013 | G20: =MONTH(Sheet1!$C20) -> 8 | H20: =WEEKDAY(Sheet1!$C20) -> 5
A21: CA-2012-AB10015140-40974 | B21: Aaron Bergman | C21: 40974 | D21: 40975 | E21: =IF(Sheet1!$D21<=TODAY(),"COMPLETED","PENDING") -> COMPLETED | F21: =YEAR(Sheet1!$C21) -> 2012 | G21: =MONTH(Sheet1!$C21) -> 3 | H21: =WEEKDAY(Sheet1!$C21) -> 3
A22: IN-2012-JK1532527-41030 | B22: Jason Klamczynski | C22: 41030 | D22: 41031 | E22: =IF(Sheet1!$D22<=TODAY(),"COMPLETED","PENDING") -> COMPLETED | F22: =YEAR(Sheet1!$C22) -> 2012 | G22: =MONTH(Sheet1!$C22) -> 5 | H22: =WEEKDAY(Sheet1!$C22) -> 3
A23: ES-2014-LB16795139-41697 | B23: Laurel Beltran | C23: 41697 | D23: 41699 | E23: =IF(Sheet1!$D23<=TODAY(),"COMPLETED","PENDING") -> COMPLETED | F23: =YEAR(Sheet1!$C23) -> 2014 | G23: =MONTH(Sheet1!$C23) -> 2 | H23: =WEEKDAY(Sheet1!$C23) -> 5
A24: US-2015-NP1832582-42216 | B24: Naresj Patel | C24: 42216 | D24: 42217 | E24: =IF(Sheet1!$D24<=TODAY(),"COMPLETED","PENDING") -> COMPLETED | F24: =YEAR(Sheet1!$C24) -> 2015 | G24: =MONTH(Sheet1!$C24) -> 7 | H24: =WEEKDAY(Sheet1!$C24) -> 6
A25: MX-2015-VD2167039-42252 | B25: Valerie Dominguez | C25: 42252 | D25: 42255 | E25: =IF(Sheet1!$D25<=TODAY(),"COMPLETED","PENDING") -> COMPLETED | F25: =YEAR(Sheet1!$C25) -> 2015 | G25: =MONTH(Sheet1!$C25) -> 9 | H25: =WEEKDAY(Sheet1!$C25) -> 7
A26: IN-2012-PB19210127-41259 | B26: Phillip Breyer | C26: 41259 | D26: 41262 | E26: =IF(Sheet1!$D26<=TODAY(),"COMPLETED","PENDING") -> COMPLETED | F26: =YEAR(Sheet1!$C26) -> 2012 | G26: =MONTH(Sheet1!$C26) -> 12 | H26: =WEEKDAY(Sheet1!$C26) -> 1
A27: ES-2012-EB1411048-40981 | B27: Eugene Barchas | D27: 40984 | E27: =IF(Sheet1!$D27<=TODAY(),"COMPLETED","PENDING") -> COMPLETED | F27: =YEAR(Sheet1!$C27) -> 1900 | G27: =MONTH(Sheet1!$C27) -> 1 | H27: =WEEKDAY(Sheet1!$C27) -> 7
A28: CA-2012-AH10030140-41020 | B28: Aaron Hawkins | C28: 41020 | D28: 41022 | E28: =IF(Sheet1!$D28<=TODAY(),"COMPLETED","PENDING") -> COMPLETED | F28: =YEAR(Sheet1!$C28) -> 2012 | G28: =MONTH(Sheet1!$C28) -> 4 | H28: =WEEKDAY(Sheet1!$C28) -> 7
A29: IN-2013-BP1123058-41329 | B29: Benjamin Patterson | C29: 41329 | D29: 41329 | E29: =IF(Sheet1!$D29<=TODAY(),"COMPLETED","PENDING") -> COMPLETED | F29: =YEAR(Sheet1!$C29) -> 2013 | G29: =MONTH(Sheet1!$C29) -> 2 | H29: =WEEKDAY(Sheet1!$C29) -> 1
A30: US-2012-RR1952536-41270 | B30: Rick Reed | C30: 41270 | E30: =IF(Sheet1!$D30<=TODAY(),"COMPLETED","PENDING") -> PENDING | F30: =YEAR(Sheet1!$C30) -> 2012 | G30: =MONTH(Sheet1!$C30) -> 12 | H30: =WEEKDAY(Sheet1!$C30) -> 5
A31: ES-2013-BS1136545-41472 | B31: Bill Shonely | C31: 41472 | D31: 41474 | E31: =IF(Sheet1!$D31<=TODAY(),"COMPLETED","PENDING") -> COMPLETED | F31: =YEAR(Sheet1!$C31) -> 2013 | G31: =MONTH(Sheet1!$C31) -> 7 | H31: =WEEKDAY(Sheet1!$C31) -> 4
A32: CA-2013-AH1003014-041635 | B32: Aaron Hawkins | C32: 41635 | D32: 41639 | E32: =IF(Sheet1!$D32<=TODAY(),"COMPLETED","PENDING") -> COMPLETED | F32: =YEAR(Sheet1!$C32) -> 2013 | G32: =MONTH(Sheet1!$C32) -> 12 | H32: =WEEKDAY(Sheet1!$C32) -> 6
A33: IN-2012-DP131057-41215 | B33: Dave Poirier | C33: 32/13/2020 | D33: 41217 | E33: =IF(Sheet1!$D33<=TODAY(),"COMPLETED","PENDING") -> COMPLETED | F33: Null | G33: =MONTH(Sheet1!$C33) -> #VALUE! | H33: =WEEKDAY(Sheet1!$C33) -> #VALUE!
A34: CA-2013-AH10030140-41635 | B34: Aaron Hawkins | C34: 41635 | D34: 41639 | E34: =IF(Sheet1!$D34<=TODAY(),"COMPLETED","PENDING") -> COMPLETED | F34: =YEAR(Sheet1!$C34) -> 2013 | G34: =MONTH(Sheet1!$C34) -> 12 | H34: =WEEKDAY(Sheet1!$C34) -> 6
A35: CG-2012-AH1003033-41165 | B35: Aaron Hawkins | C35: 41165 | D35: 41166 | E35: =IF(Sheet1!$D35<=TODAY(),"COMPLETED","PENDING") -> COMPLETED | F35: =YEAR(Sheet1!$C35) -> 2012 | G35: =MONTH(Sheet1!$C35) -> 9 | H35: =WEEKDAY(Sheet1!$C35) -> 5
A36: CA-2012-AH10030140-41041 | B36: Aaron Hawkins | C36: 41041 | E36: =IF(Sheet1!$D36<=TODAY(),"COMPLETED","PENDING") -> COMPLETED | F36: =YEAR(Sheet1!$C36) -> 2012 | G36: =MONTH(Sheet1!$C36) -> 5 | H36: =WEEKDAY(Sheet1!$C36) -> 7
A37: CA-2012-AH10030140-41273 | C37: 41273 | D37: 41274 | E37: =IF(Sheet1!$D37<=TODAY(),"COMPLETED","PENDING") -> COMPLETED | F37: =YEAR(Sheet1!$C37) -> 2012 | G37: =MONTH(Sheet1!$C37) -> 12 | H37: =WEEKDAY(Sheet1!$C37) -> 1
A38: ES-2015-PO18865139-42018 | C38: 42018 | D38: 42022 | E38: =IF(Sheet1!$D38<=TODAY(),"COMPLETED","PENDING") -> COMPLETED | F38: =YEAR(Sheet1!$C38) -> 2015 | G38: =MONTH(Sheet1!$C38) -> 1 | H38: =WEEKDAY(Sheet1!$C38) -> 4
A39: IN-2012-DL128657-40918 | B39: Dan Lawera | C39: 40918 | D39: 41214 | E39: =IF(Sheet1!$D39<=TODAY(),"COMPLETED","PENDING") -> COMPLETED | F39: =YEAR(Sheet1!$C39) -> 2012 | G39: =MONTH(Sheet1!$C39) -> 1 | H39: =WEEKDAY(Sheet1!$C39) -> 3
A40: ID-2014-JB1600059-41873 | B40: Joy Bell- | C40: 41873 | D40: 41877 | E40: =IF(Sheet1!$D40<=TODAY(),"COMPLETED","PENDING") -> COMPLETED | F40: =YEAR(Sheet1!$C40) -> 2014 | G40: =MONTH(Sheet1!$C40) -> 8 | H40: =WEEKDAY(Sheet1!$C40) -> 6
...

Sheet Sheet2
